import React from 'react';
import { render, screen, fireEvent } from '@testing-library/react';
import ErrorBoundary from '../ErrorBoundary';

// Component that throws an error for testing
const ThrowError = ({ shouldThrow }) => {
  if (shouldThrow) {
    throw new Error('Test error');
  }
  return <div>No error</div>;
};

// Mock console.error to avoid noise in test output
const originalError = console.error;
beforeAll(() => {
  console.error = jest.fn();
});

afterAll(() => {
  console.error = originalError;
});

describe('ErrorBoundary', () => {
  beforeEach(() => {
    console.error.mockClear();
  });

  test('renders children when there is no error', () => {
    render(
      <ErrorBoundary>
        <ThrowError shouldThrow={false} />
      </ErrorBoundary>
    );

    expect(screen.getByText('No error')).toBeInTheDocument();
  });

  test('renders error UI when there is an error', () => {
    render(
      <ErrorBoundary>
        <ThrowError shouldThrow={true} />
      </ErrorBoundary>
    );

    expect(screen.getByText('Something went wrong')).toBeInTheDocument();
    expect(screen.getByText(/An unexpected error occurred/)).toBeInTheDocument();
    expect(screen.getByText('Try Again')).toBeInTheDocument();
    expect(screen.getByText('Reload Page')).toBeInTheDocument();
  });

  test('displays custom fallback message when provided', () => {
    const customMessage = 'Custom error message for testing';
    
    render(
      <ErrorBoundary fallbackMessage={customMessage}>
        <ThrowError shouldThrow={true} />
      </ErrorBoundary>
    );

    expect(screen.getByText(customMessage)).toBeInTheDocument();
  });

  test('logs error details to console', () => {
    render(
      <ErrorBoundary>
        <ThrowError shouldThrow={true} />
      </ErrorBoundary>
    );

    expect(console.error).toHaveBeenCalledWith(
      'ErrorBoundary caught an error:',
      expect.any(Error),
      expect.any(Object)
    );
  });

  test('shows error details in development mode', () => {
    const originalEnv = process.env.NODE_ENV;
    process.env.NODE_ENV = 'development';

    render(
      <ErrorBoundary>
        <ThrowError shouldThrow={true} />
      </ErrorBoundary>
    );

    expect(screen.getByText('Error Details (Development Only)')).toBeInTheDocument();
    
    // Click to expand details
    fireEvent.click(screen.getByText('Error Details (Development Only)'));
    
    expect(screen.getByText(/Error:/)).toBeInTheDocument();
    expect(screen.getByText(/Test error/)).toBeInTheDocument();

    process.env.NODE_ENV = originalEnv;
  });

  test('hides error details in production mode', () => {
    const originalEnv = process.env.NODE_ENV;
    process.env.NODE_ENV = 'production';

    render(
      <ErrorBoundary>
        <ThrowError shouldThrow={true} />
      </ErrorBoundary>
    );

    expect(screen.queryByText('Error Details (Development Only)')).not.toBeInTheDocument();

    process.env.NODE_ENV = originalEnv;
  });

  test('retry button resets error state', () => {
    const { rerender } = render(
      <ErrorBoundary>
        <ThrowError shouldThrow={true} />
      </ErrorBoundary>
    );

    // Error UI should be visible
    expect(screen.getByText('Something went wrong')).toBeInTheDocument();

    // Click retry button
    fireEvent.click(screen.getByText('Try Again'));

    // Re-render with no error
    rerender(
      <ErrorBoundary>
        <ThrowError shouldThrow={false} />
      </ErrorBoundary>
    );

    // Should show normal content
    expect(screen.getByText('No error')).toBeInTheDocument();
    expect(screen.queryByText('Something went wrong')).not.toBeInTheDocument();
  });

  test('reload page button triggers page reload', () => {
    // Mock window.location.reload
    const mockReload = jest.fn();
    Object.defineProperty(window, 'location', {
      value: {
        reload: mockReload,
      },
      writable: true,
    });

    render(
      <ErrorBoundary>
        <ThrowError shouldThrow={true} />
      </ErrorBoundary>
    );

    fireEvent.click(screen.getByText('Reload Page'));

    expect(mockReload).toHaveBeenCalled();
  });

  test('handles multiple errors correctly', () => {
    const { rerender } = render(
      <ErrorBoundary>
        <ThrowError shouldThrow={true} />
      </ErrorBoundary>
    );

    // First error
    expect(screen.getByText('Something went wrong')).toBeInTheDocument();

    // Reset and throw different error
    fireEvent.click(screen.getByText('Try Again'));
    
    rerender(
      <ErrorBoundary>
        <ThrowError shouldThrow={true} />
      </ErrorBoundary>
    );

    // Should still show error UI
    expect(screen.getByText('Something went wrong')).toBeInTheDocument();
  });

  test('error boundary catches errors from deeply nested components', () => {
    const DeepComponent = () => {
      throw new Error('Deep error');
    };

    const NestedComponent = () => (
      <div>
        <div>
          <DeepComponent />
        </div>
      </div>
    );

    render(
      <ErrorBoundary>
        <NestedComponent />
      </ErrorBoundary>
    );

    expect(screen.getByText('Something went wrong')).toBeInTheDocument();
    expect(console.error).toHaveBeenCalledWith(
      'ErrorBoundary caught an error:',
      expect.any(Error),
      expect.any(Object)
    );
  });
});